<?xml version="1.0" ?>
<robot name="hashcode_model" xmlns:xacro="http://www.ros.org/wiki/xacro">

<xacro:include filename="$(find hashcode_model_description)/urdf/materials.xacro" />
<xacro:include filename="$(find hashcode_model_description)/urdf/hashcode_model.trans" />
<xacro:include filename="$(find hashcode_model_description)/urdf/hashcode_model.gazebo" />
<link name="base_link">
  <inertial>
    <origin xyz="0.0 0.0 0.0" rpy="0 0 0"/>
    <mass value="0.0"/>
    <inertia ixx="0.0" iyy="0.0" izz="0.0" ixy="0.0" iyz="0.0" ixz="0.0"/>
  </inertial>
  <visual>
    <origin xyz="0 0 0" rpy="0 0 0"/>
    <geometry>
      <mesh filename="package://hashcode_model_description/meshes/base_link.stl" scale="0.001 0.001 0.001"/>
    </geometry>
    <material name="silver"/>
  </visual>
  <collision>
    <origin xyz="0 0 0" rpy="0 0 0"/>
    <geometry>
      <mesh filename="package://hashcode_model_description/meshes/base_link.stl" scale="0.001 0.001 0.001"/>
    </geometry>
  </collision>
</link>

<link name="lidar_1_1">
  <inertial>
    <origin xyz="-8.195638542818351e-10 0.0 0.020000000000000004" rpy="0 0 0"/>
    <mass value="0.22195352759084938"/>
    <inertia ixx="4.2e-05" iyy="4.2e-05" izz="2.5e-05" ixy="0.0" iyz="-0.0" ixz="0.0"/>
  </inertial>
  <visual>
    <origin xyz="0.055 -0.0 -0.043" rpy="0 0 0"/>
    <geometry>
      <mesh filename="package://hashcode_model_description/meshes/lidar_1_1.stl" scale="0.001 0.001 0.001"/>
    </geometry>
    <material name="silver"/>
  </visual>
  <collision>
    <origin xyz="0.055 -0.0 -0.043" rpy="0 0 0"/>
    <geometry>
      <mesh filename="package://hashcode_model_description/meshes/lidar_1_1.stl" scale="0.001 0.001 0.001"/>
    </geometry>
  </collision>
</link>

<link name="end_effector_right_1_1">
  <inertial>
    <origin xyz="0.017918101862081898 -1.490116155467014e-10 0.012601828357699213" rpy="0 0 0"/>
    <mass value="0.0023314500694826164"/>
    <inertia ixx="0.0" iyy="0.0" izz="0.0" ixy="-0.0" iyz="0.0" ixz="-0.0"/>
  </inertial>
  <visual>
    <origin xyz="-0.1787 0.011 -0.162982" rpy="0 0 0"/>
    <geometry>
      <mesh filename="package://hashcode_model_description/meshes/end_effector_right_1_1.stl" scale="0.001 0.001 0.001"/>
    </geometry>
    <material name="silver"/>
  </visual>
  <collision>
    <origin xyz="-0.1787 0.011 -0.162982" rpy="0 0 0"/>
    <geometry>
      <mesh filename="package://hashcode_model_description/meshes/end_effector_right_1_1.stl" scale="0.001 0.001 0.001"/>
    </geometry>
  </collision>
</link>

<link name="end_effector_left_1_1">
  <inertial>
    <origin xyz="0.017918101862081898 -5.96046467390976e-11 0.012601828357699213" rpy="0 0 0"/>
    <mass value="0.0023314500694826164"/>
    <inertia ixx="0.0" iyy="0.0" izz="0.0" ixy="0.0" iyz="0.0" ixz="-0.0"/>
  </inertial>
  <visual>
    <origin xyz="-0.1787 0.005 -0.162982" rpy="0 0 0"/>
    <geometry>
      <mesh filename="package://hashcode_model_description/meshes/end_effector_left_1_1.stl" scale="0.001 0.001 0.001"/>
    </geometry>
    <material name="silver"/>
  </visual>
  <collision>
    <origin xyz="-0.1787 0.005 -0.162982" rpy="0 0 0"/>
    <geometry>
      <mesh filename="package://hashcode_model_description/meshes/end_effector_left_1_1.stl" scale="0.001 0.001 0.001"/>
    </geometry>
  </collision>
</link>

<link name="arm_link_2_1_1">
  <inertial>
    <origin xyz="0.029590863295727146 -0.0059869220609548215 0.017091845797454985" rpy="0 0 0"/>
    <mass value="0.00449658000123918"/>
    <inertia ixx="1e-06" iyy="2e-06" izz="2e-06" ixy="0.0" iyz="0.0" ixz="-1e-06"/>
  </inertial>
  <visual>
    <origin xyz="-0.121128 0.002 -0.125701" rpy="0 0 0"/>
    <geometry>
      <mesh filename="package://hashcode_model_description/meshes/arm_link_2_1_1.stl" scale="0.001 0.001 0.001"/>
    </geometry>
    <material name="silver"/>
  </visual>
  <collision>
    <origin xyz="-0.121128 0.002 -0.125701" rpy="0 0 0"/>
    <geometry>
      <mesh filename="package://hashcode_model_description/meshes/arm_link_2_1_1.stl" scale="0.001 0.001 0.001"/>
    </geometry>
  </collision>
</link>

<link name="arm_link_1_1_1">
  <inertial>
    <origin xyz="0.061334959889755715 -0.006 0.03367970343905149" rpy="0 0 0"/>
    <mass value="0.008748266414448754"/>
    <inertia ixx="4e-06" iyy="1.6e-05" izz="1.2e-05" ixy="0.0" iyz="0.0" ixz="-7e-06"/>
  </inertial>
  <visual>
    <origin xyz="-0.0 -0.01 -0.0575" rpy="0 0 0"/>
    <geometry>
      <mesh filename="package://hashcode_model_description/meshes/arm_link_1_1_1.stl" scale="0.001 0.001 0.001"/>
    </geometry>
    <material name="silver"/>
  </visual>
  <collision>
    <origin xyz="-0.0 -0.01 -0.0575" rpy="0 0 0"/>
    <geometry>
      <mesh filename="package://hashcode_model_description/meshes/arm_link_1_1_1.stl" scale="0.001 0.001 0.001"/>
    </geometry>
  </collision>
</link>

<link name="left_wheel_back_1_1">
  <inertial>
    <origin xyz="0.0 0.007499999999999986 3.469446951953614e-18" rpy="0 0 0"/>
    <mass value="0.027390760948486005"/>
    <inertia ixx="5e-06" iyy="9e-06" izz="5e-06" ixy="0.0" iyz="0.0" ixz="-0.0"/>
  </inertial>
  <visual>
    <origin xyz="0.075 -0.05 -0.025" rpy="0 0 0"/>
    <geometry>
      <mesh filename="package://hashcode_model_description/meshes/left_wheel_back_1_1.stl" scale="0.001 0.001 0.001"/>
    </geometry>
    <material name="silver"/>
  </visual>
  <collision>
    <origin xyz="0.075 -0.05 -0.025" rpy="0 0 0"/>
    <geometry>
      <mesh filename="package://hashcode_model_description/meshes/left_wheel_back_1_1.stl" scale="0.001 0.001 0.001"/>
    </geometry>
  </collision>
</link>

<link name="right_wheel_front_1_1">
  <inertial>
    <origin xyz="0.0 -0.007500000000000007 3.469446951953614e-18" rpy="0 0 0"/>
    <mass value="0.027390760948486005"/>
    <inertia ixx="5e-06" iyy="9e-06" izz="5e-06" ixy="0.0" iyz="-0.0" ixz="0.0"/>
  </inertial>
  <visual>
    <origin xyz="-0.075 0.05 -0.025" rpy="0 0 0"/>
    <geometry>
      <mesh filename="package://hashcode_model_description/meshes/right_wheel_front_1_1.stl" scale="0.001 0.001 0.001"/>
    </geometry>
    <material name="silver"/>
  </visual>
  <collision>
    <origin xyz="-0.075 0.05 -0.025" rpy="0 0 0"/>
    <geometry>
      <mesh filename="package://hashcode_model_description/meshes/right_wheel_front_1_1.stl" scale="0.001 0.001 0.001"/>
    </geometry>
  </collision>
</link>

<link name="right_wheel_back_1_1">
  <inertial>
    <origin xyz="0.0 -0.007500000000000007 3.469446951953614e-18" rpy="0 0 0"/>
    <mass value="0.027390760948486005"/>
    <inertia ixx="5e-06" iyy="9e-06" izz="5e-06" ixy="-0.0" iyz="-0.0" ixz="-0.0"/>
  </inertial>
  <visual>
    <origin xyz="0.075 0.05 -0.025" rpy="0 0 0"/>
    <geometry>
      <mesh filename="package://hashcode_model_description/meshes/right_wheel_back_1_1.stl" scale="0.001 0.001 0.001"/>
    </geometry>
    <material name="silver"/>
  </visual>
  <collision>
    <origin xyz="0.075 0.05 -0.025" rpy="0 0 0"/>
    <geometry>
      <mesh filename="package://hashcode_model_description/meshes/right_wheel_back_1_1.stl" scale="0.001 0.001 0.001"/>
    </geometry>
  </collision>
</link>

<link name="left_wheel_front_1_1">
  <inertial>
    <origin xyz="0.0 0.007499999999999986 3.469446951953614e-18" rpy="0 0 0"/>
    <mass value="0.027390760948486005"/>
    <inertia ixx="5e-06" iyy="9e-06" izz="5e-06" ixy="-0.0" iyz="0.0" ixz="0.0"/>
  </inertial>
  <visual>
    <origin xyz="-0.075 -0.05 -0.025" rpy="0 0 0"/>
    <geometry>
      <mesh filename="package://hashcode_model_description/meshes/left_wheel_front_1_1.stl" scale="0.001 0.001 0.001"/>
    </geometry>
    <material name="silver"/>
  </visual>
  <collision>
    <origin xyz="-0.075 -0.05 -0.025" rpy="0 0 0"/>
    <geometry>
      <mesh filename="package://hashcode_model_description/meshes/left_wheel_front_1_1.stl" scale="0.001 0.001 0.001"/>
    </geometry>
  </collision>
</link>

<joint name="Revolute 26" type="continuous">
  <origin xyz="-0.055 0.0 0.043" rpy="0 0 0"/>
  <parent link="base_link"/>
  <child link="lidar_1_1"/>
  <axis xyz="0.0 0.0 1.0"/>
</joint>

<joint name="Revolute 28" type="revolute">
  <origin xyz="0.057572 -0.009 0.037281" rpy="0 0 0"/>
  <parent link="arm_link_2_1_1"/>
  <child link="end_effector_right_1_1"/>
  <axis xyz="-0.5 0.0 0.866025"/>
  <limit upper="1.047198" lower="0.0" effort="100" velocity="100"/>
</joint>

<joint name="Revolute 29" type="revolute">
  <origin xyz="0.057572 -0.003 0.037281" rpy="0 0 0"/>
  <parent link="arm_link_2_1_1"/>
  <child link="end_effector_left_1_1"/>
  <axis xyz="-0.5 0.0 0.866025"/>
  <limit upper="1.047198" lower="0.0" effort="100" velocity="100"/>
</joint>

<joint name="Revolute 30" type="revolute">
  <origin xyz="0.121128 -0.012 0.068201" rpy="0 0 0"/>
  <parent link="arm_link_1_1_1"/>
  <child link="arm_link_2_1_1"/>
  <axis xyz="0.0 -1.0 0.0"/>
  <limit upper="0.523599" lower="-1.658063" effort="100" velocity="100"/>
</joint>

<joint name="Revolute 31" type="revolute">
  <origin xyz="0.0 0.01 0.0575" rpy="0 0 0"/>
  <parent link="base_link"/>
  <child link="arm_link_1_1_1"/>
  <axis xyz="0.0 -1.0 0.0"/>
  <limit upper="1.658063" lower="0.523599" effort="100" velocity="100"/>
</joint>

<joint name="Revolute 33" type="continuous">
  <origin xyz="-0.075 0.05 0.025" rpy="0 0 0"/>
  <parent link="base_link"/>
  <child link="left_wheel_back_1_1"/>
  <axis xyz="0.0 1.0 0.0"/>
</joint>

<joint name="Revolute 34" type="continuous">
  <origin xyz="0.075 -0.05 0.025" rpy="0 0 0"/>
  <parent link="base_link"/>
  <child link="right_wheel_front_1_1"/>
  <axis xyz="0.0 -1.0 0.0"/>
</joint>

<joint name="Revolute 35" type="continuous">
  <origin xyz="-0.075 -0.05 0.025" rpy="0 0 0"/>
  <parent link="base_link"/>
  <child link="right_wheel_back_1_1"/>
  <axis xyz="0.0 -1.0 0.0"/>
</joint>

<joint name="Revolute 36" type="continuous">
  <origin xyz="0.075 0.05 0.025" rpy="0 0 0"/>
  <parent link="base_link"/>
  <child link="left_wheel_front_1_1"/>
  <axis xyz="0.0 1.0 0.0"/>
</joint>

</robot>
